<?xml version="1.0"?>
<robot name="arm_12dof">

  <link name="base_link">
    <visual>
      <origin xyz="0 0 0.025" rpy="0 0 0"/>
      <geometry><cylinder radius="0.05" length="0.05"/></geometry>
      <material name="grey"><color rgba="0.4 0.4 0.4 1"/></material>
    </visual>
    <collision>
      <origin xyz="0 0 0.025" rpy="0 0 0"/>
      <geometry><cylinder radius="0.05" length="0.05"/></geometry>
    </collision>
    <inertial>
      <mass value="2.0"/>
      <origin xyz="0 0 0.025"/>
      <inertia ixx="0.01" ixy="0" ixz="0" iyy="0.01" iyz="0" izz="0.01"/>
    </inertial>
  </link>

  <link name="link_0">
    <visual>
      <origin xyz="0 0 0.035" rpy="0 0 0"/>
      <geometry><cylinder radius="0.015" length="0.07"/></geometry>
      <material name="m_link_0"><color rgba="0.2 0.4 0.8 1"/></material>
    </visual>
    <collision>
      <origin xyz="0 0 0.035" rpy="0 0 0"/>
      <geometry><cylinder radius="0.015" length="0.07"/></geometry>
    </collision>
    <inertial>
      <mass value="0.4"/>
      <origin xyz="0 0 0.035"/>
      <inertia ixx="0.000186" ixy="0" ixz="0"
               iyy="0.000186" iyz="0" izz="0.000045"/>
    </inertial>
  </link>

  <joint name="joint_0" type="revolute">
    <parent link="base_link"/>
    <child link="link_0"/>
    <origin xyz="0 0 0.05" rpy="0 0 0"/>
    <axis xyz="0 0 1"/>
    <limit lower="-3.14" upper="3.14" effort="100" velocity="2.0"/>
    <dynamics damping="0.5" friction="0.1"/>
  </joint>

  <link name="link_1">
    <visual>
      <origin xyz="0 0 0.035" rpy="0 0 0"/>
      <geometry><cylinder radius="0.015" length="0.07"/></geometry>
      <material name="m_link_1"><color rgba="0.2 0.6 0.8 1"/></material>
    </visual>
    <collision>
      <origin xyz="0 0 0.035" rpy="0 0 0"/>
      <geometry><cylinder radius="0.015" length="0.07"/></geometry>
    </collision>
    <inertial>
      <mass value="0.4"/>
      <origin xyz="0 0 0.035"/>
      <inertia ixx="0.000186" ixy="0" ixz="0"
               iyy="0.000186" iyz="0" izz="0.000045"/>
    </inertial>
  </link>

  <joint name="joint_1" type="revolute">
    <parent link="link_0"/>
    <child link="link_1"/>
    <origin xyz="0 0 0.07" rpy="0 0 0"/>
    <axis xyz="0 1 0"/>
    <limit lower="-3.14" upper="3.14" effort="100" velocity="2.0"/>
    <dynamics damping="0.5" friction="0.1"/>
  </joint>

  <link name="link_2">
    <visual>
      <origin xyz="0 0 0.035" rpy="0 0 0"/>
      <geometry><cylinder radius="0.015" length="0.07"/></geometry>
      <material name="m_link_2"><color rgba="0.3 0.7 0.5 1"/></material>
    </visual>
    <collision>
      <origin xyz="0 0 0.035" rpy="0 0 0"/>
      <geometry><cylinder radius="0.015" length="0.07"/></geometry>
    </collision>
    <inertial>
      <mass value="0.4"/>
      <origin xyz="0 0 0.035"/>
      <inertia ixx="0.000186" ixy="0" ixz="0"
               iyy="0.000186" iyz="0" izz="0.000045"/>
    </inertial>
  </link>

  <joint name="joint_2" type="revolute">
    <parent link="link_1"/>
    <child link="link_2"/>
    <origin xyz="0 0 0.07" rpy="0 0 0"/>
    <axis xyz="1 0 0"/>
    <limit lower="-3.14" upper="3.14" effort="100" velocity="2.0"/>
    <dynamics damping="0.5" friction="0.1"/>
  </joint>

  <link name="link_3">
    <visual>
      <origin xyz="0 0 0.035" rpy="0 0 0"/>
      <geometry><cylinder radius="0.015" length="0.07"/></geometry>
      <material name="m_link_3"><color rgba="0.5 0.7 0.3 1"/></material>
    </visual>
    <collision>
      <origin xyz="0 0 0.035" rpy="0 0 0"/>
      <geometry><cylinder radius="0.015" length="0.07"/></geometry>
    </collision>
    <inertial>
      <mass value="0.4"/>
      <origin xyz="0 0 0.035"/>
      <inertia ixx="0.000186" ixy="0" ixz="0"
               iyy="0.000186" iyz="0" izz="0.000045"/>
    </inertial>
  </link>

  <joint name="joint_3" type="revolute">
    <parent link="link_2"/>
    <child link="link_3"/>
    <origin xyz="0 0 0.07" rpy="0 0 0"/>
    <axis xyz="0 0 1"/>
    <limit lower="-3.14" upper="3.14" effort="100" velocity="2.0"/>
    <dynamics damping="0.5" friction="0.1"/>
  </joint>

  <link name="link_4">
    <visual>
      <origin xyz="0 0 0.035" rpy="0 0 0"/>
      <geometry><cylinder radius="0.015" length="0.07"/></geometry>
      <material name="m_link_4"><color rgba="0.7 0.6 0.2 1"/></material>
    </visual>
    <collision>
      <origin xyz="0 0 0.035" rpy="0 0 0"/>
      <geometry><cylinder radius="0.015" length="0.07"/></geometry>
    </collision>
    <inertial>
      <mass value="0.4"/>
      <origin xyz="0 0 0.035"/>
      <inertia ixx="0.000186" ixy="0" ixz="0"
               iyy="0.000186" iyz="0" izz="0.000045"/>
    </inertial>
  </link>

  <joint name="joint_4" type="revolute">
    <parent link="link_3"/>
    <child link="link_4"/>
    <origin xyz="0 0 0.07" rpy="0 0 0"/>
    <axis xyz="0 1 0"/>
    <limit lower="-3.14" upper="3.14" effort="100" velocity="2.0"/>
    <dynamics damping="0.5" friction="0.1"/>
  </joint>

  <link name="link_5">
    <visual>
      <origin xyz="0 0 0.035" rpy="0 0 0"/>
      <geometry><cylinder radius="0.015" length="0.07"/></geometry>
      <material name="m_link_5"><color rgba="0.8 0.4 0.2 1"/></material>
    </visual>
    <collision>
      <origin xyz="0 0 0.035" rpy="0 0 0"/>
      <geometry><cylinder radius="0.015" length="0.07"/></geometry>
    </collision>
    <inertial>
      <mass value="0.4"/>
      <origin xyz="0 0 0.035"/>
      <inertia ixx="0.000186" ixy="0" ixz="0"
               iyy="0.000186" iyz="0" izz="0.000045"/>
    </inertial>
  </link>

  <joint name="joint_5" type="revolute">
    <parent link="link_4"/>
    <child link="link_5"/>
    <origin xyz="0 0 0.07" rpy="0 0 0"/>
    <axis xyz="1 0 0"/>
    <limit lower="-3.14" upper="3.14" effort="100" velocity="2.0"/>
    <dynamics damping="0.5" friction="0.1"/>
  </joint>

  <link name="link_6">
    <visual>
      <origin xyz="0 0 0.035" rpy="0 0 0"/>
      <geometry><cylinder radius="0.015" length="0.07"/></geometry>
      <material name="m_link_6"><color rgba="0.8 0.2 0.3 1"/></material>
    </visual>
    <collision>
      <origin xyz="0 0 0.035" rpy="0 0 0"/>
      <geometry><cylinder radius="0.015" length="0.07"/></geometry>
    </collision>
    <inertial>
      <mass value="0.4"/>
      <origin xyz="0 0 0.035"/>
      <inertia ixx="0.000186" ixy="0" ixz="0"
               iyy="0.000186" iyz="0" izz="0.000045"/>
    </inertial>
  </link>

  <joint name="joint_6" type="revolute">
    <parent link="link_5"/>
    <child link="link_6"/>
    <origin xyz="0 0 0.07" rpy="0 0 0"/>
    <axis xyz="0 0 1"/>
    <limit lower="-3.14" upper="3.14" effort="100" velocity="2.0"/>
    <dynamics damping="0.5" friction="0.1"/>
  </joint>

  <link name="link_7">
    <visual>
      <origin xyz="0 0 0.035" rpy="0 0 0"/>
      <geometry><cylinder radius="0.015" length="0.07"/></geometry>
      <material name="m_link_7"><color rgba="0.6 0.2 0.7 1"/></material>
    </visual>
    <collision>
      <origin xyz="0 0 0.035" rpy="0 0 0"/>
      <geometry><cylinder radius="0.015" length="0.07"/></geometry>
    </collision>
    <inertial>
      <mass value="0.4"/>
      <origin xyz="0 0 0.035"/>
      <inertia ixx="0.000186" ixy="0" ixz="0"
               iyy="0.000186" iyz="0" izz="0.000045"/>
    </inertial>
  </link>

  <joint name="joint_7" type="revolute">
    <parent link="link_6"/>
    <child link="link_7"/>
    <origin xyz="0 0 0.07" rpy="0 0 0"/>
    <axis xyz="0 1 0"/>
    <limit lower="-3.14" upper="3.14" effort="100" velocity="2.0"/>
    <dynamics damping="0.5" friction="0.1"/>
  </joint>

  <link name="link_8">
    <visual>
      <origin xyz="0 0 0.035" rpy="0 0 0"/>
      <geometry><cylinder radius="0.015" length="0.07"/></geometry>
      <material name="m_link_8"><color rgba="0.4 0.2 0.8 1"/></material>
    </visual>
    <collision>
      <origin xyz="0 0 0.035" rpy="0 0 0"/>
      <geometry><cylinder radius="0.015" length="0.07"/></geometry>
    </collision>
    <inertial>
      <mass value="0.4"/>
      <origin xyz="0 0 0.035"/>
      <inertia ixx="0.000186" ixy="0" ixz="0"
               iyy="0.000186" iyz="0" izz="0.000045"/>
    </inertial>
  </link>

  <joint name="joint_8" type="revolute">
    <parent link="link_7"/>
    <child link="link_8"/>
    <origin xyz="0 0 0.07" rpy="0 0 0"/>
    <axis xyz="1 0 0"/>
    <limit lower="-3.14" upper="3.14" effort="100" velocity="2.0"/>
    <dynamics damping="0.5" friction="0.1"/>
  </joint>

  <link name="link_9">
    <visual>
      <origin xyz="0 0 0.035" rpy="0 0 0"/>
      <geometry><cylinder radius="0.015" length="0.07"/></geometry>
      <material name="m_link_9"><color rgba="0.2 0.3 0.8 1"/></material>
    </visual>
    <collision>
      <origin xyz="0 0 0.035" rpy="0 0 0"/>
      <geometry><cylinder radius="0.015" length="0.07"/></geometry>
    </collision>
    <inertial>
      <mass value="0.4"/>
      <origin xyz="0 0 0.035"/>
      <inertia ixx="0.000186" ixy="0" ixz="0"
               iyy="0.000186" iyz="0" izz="0.000045"/>
    </inertial>
  </link>

  <joint name="joint_9" type="revolute">
    <parent link="link_8"/>
    <child link="link_9"/>
    <origin xyz="0 0 0.07" rpy="0 0 0"/>
    <axis xyz="0 0 1"/>
    <limit lower="-3.14" upper="3.14" effort="100" velocity="2.0"/>
    <dynamics damping="0.5" friction="0.1"/>
  </joint>

  <link name="link_10">
    <visual>
      <origin xyz="0 0 0.035" rpy="0 0 0"/>
      <geometry><cylinder radius="0.015" length="0.07"/></geometry>
      <material name="m_link_10"><color rgba="0.2 0.5 0.6 1"/></material>
    </visual>
    <collision>
      <origin xyz="0 0 0.035" rpy="0 0 0"/>
      <geometry><cylinder radius="0.015" length="0.07"/></geometry>
    </collision>
    <inertial>
      <mass value="0.4"/>
      <origin xyz="0 0 0.035"/>
      <inertia ixx="0.000186" ixy="0" ixz="0"
               iyy="0.000186" iyz="0" izz="0.000045"/>
    </inertial>
  </link>

  <joint name="joint_10" type="revolute">
    <parent link="link_9"/>
    <child link="link_10"/>
    <origin xyz="0 0 0.07" rpy="0 0 0"/>
    <axis xyz="0 1 0"/>
    <limit lower="-3.14" upper="3.14" effort="100" velocity="2.0"/>
    <dynamics damping="0.5" friction="0.1"/>
  </joint>

  <link name="link_11">
    <visual>
      <origin xyz="0 0 0.035" rpy="0 0 0"/>
      <geometry><cylinder radius="0.015" length="0.07"/></geometry>
      <material name="m_link_11"><color rgba="0.3 0.6 0.4 1"/></material>
    </visual>
    <collision>
      <origin xyz="0 0 0.035" rpy="0 0 0"/>
      <geometry><cylinder radius="0.015" length="0.07"/></geometry>
    </collision>
    <inertial>
      <mass value="0.4"/>
      <origin xyz="0 0 0.035"/>
      <inertia ixx="0.000186" ixy="0" ixz="0"
               iyy="0.000186" iyz="0" izz="0.000045"/>
    </inertial>
  </link>

  <joint name="joint_11" type="revolute">
    <parent link="link_10"/>
    <child link="link_11"/>
    <origin xyz="0 0 0.07" rpy="0 0 0"/>
    <axis xyz="0 0 1"/>
    <limit lower="-3.14" upper="3.14" effort="100" velocity="2.0"/>
    <dynamics damping="0.5" friction="0.1"/>
  </joint>
</robot>